ERROR:    Exception in ASGI application
Traceback (most recent call last):
  File "C:\Users\dipan\Documents\Code\lit-eracy\backend\.venv\Lib\site-packages\uvicorn\protocols\http\httptools_impl.py", line 401, in run_asgi
    result = await app(  # type: ignore[func-returns-value]
             ^^^^^^^^^^^^^^^^^^^^^^^^^^^^^^^^^^^^^^^^^^^^^^
        self.scope, self.receive, self.send
        ^^^^^^^^^^^^^^^^^^^^^^^^^^^^^^^^^^^
    )
    ^
  File "C:\Users\dipan\Documents\Code\lit-eracy\backend\.venv\Lib\site-packages\uvicorn\middleware\proxy_headers.py", line 60, in __call__
    return await self.app(scope, receive, send)
           ^^^^^^^^^^^^^^^^^^^^^^^^^^^^^^^^^^^^
  File "C:\Users\dipan\Documents\Code\lit-eracy\backend\.venv\Lib\site-packages\fastapi\applications.py", line 1054, in __call__     
    await super().__call__(scope, receive, send)
  File "C:\Users\dipan\Documents\Code\lit-eracy\backend\.venv\Lib\site-packages\starlette\applications.py", line 113, in __call__    
    await self.middleware_stack(scope, receive, send)
  File "C:\Users\dipan\Documents\Code\lit-eracy\backend\.venv\Lib\site-packages\starlette\middleware\errors.py", line 187, in __call__
    raise exc
  File "C:\Users\dipan\Documents\Code\lit-eracy\backend\.venv\Lib\site-packages\starlette\middleware\errors.py", line 165, in __call__
    await self.app(scope, receive, _send)
  File "C:\Users\dipan\Documents\Code\lit-eracy\backend\.venv\Lib\site-packages\starlette\middleware\cors.py", line 85, in __call__  
    await self.app(scope, receive, send)
  File "C:\Users\dipan\Documents\Code\lit-eracy\backend\.venv\Lib\site-packages\starlette\middleware\exceptions.py", line 62, in __call__
    await wrap_app_handling_exceptions(self.app, conn)(scope, receive, send)
  File "C:\Users\dipan\Documents\Code\lit-eracy\backend\.venv\Lib\site-packages\starlette\_exception_handler.py", line 53, in wrapped_app
    raise exc
  File "C:\Users\dipan\Documents\Code\lit-eracy\backend\.venv\Lib\site-packages\starlette\_exception_handler.py", line 42, in wrapped_app
    await app(scope, receive, sender)
  File "C:\Users\dipan\Documents\Code\lit-eracy\backend\.venv\Lib\site-packages\starlette\routing.py", line 715, in __call__
    await self.middleware_stack(scope, receive, send)
  File "C:\Users\dipan\Documents\Code\lit-eracy\backend\.venv\Lib\site-packages\starlette\routing.py", line 735, in app
    await route.handle(scope, receive, send)
  File "C:\Users\dipan\Documents\Code\lit-eracy\backend\.venv\Lib\site-packages\starlette\routing.py", line 288, in handle
    await self.app(scope, receive, send)
  File "C:\Users\dipan\Documents\Code\lit-eracy\backend\.venv\Lib\site-packages\starlette\routing.py", line 76, in app
    await wrap_app_handling_exceptions(app, request)(scope, receive, send)
  File "C:\Users\dipan\Documents\Code\lit-eracy\backend\.venv\Lib\site-packages\starlette\_exception_handler.py", line 53, in wrapped_app
    raise exc
  File "C:\Users\dipan\Documents\Code\lit-eracy\backend\.venv\Lib\site-packages\starlette\_exception_handler.py", line 42, in wrapped_app
    await app(scope, receive, sender)
  File "C:\Users\dipan\Documents\Code\lit-eracy\backend\.venv\Lib\site-packages\starlette\routing.py", line 73, in app
    response = await f(request)
               ^^^^^^^^^^^^^^^^
  File "C:\Users\dipan\Documents\Code\lit-eracy\backend\.venv\Lib\site-packages\fastapi\routing.py", line 301, in app
    raw_response = await run_endpoint_function(
                   ^^^^^^^^^^^^^^^^^^^^^^^^^^^^
    ...<3 lines>...
    )
    ^
  File "C:\Users\dipan\Documents\Code\lit-eracy\backend\.venv\Lib\site-packages\fastapi\routing.py", line 212, in run_endpoint_function
    return await dependant.call(**values)
           ^^^^^^^^^^^^^^^^^^^^^^^^^^^^^^
  File "C:\Users\dipan\Documents\Code\lit-eracy\backend\app\routes\auth.py", line 31, in register
    return crud.create_user(db=db, user=user)
           ~~~~~~~~~~~~~~~~^^^^^^^^^^^^^^^^^^
  File "C:\Users\dipan\Documents\Code\lit-eracy\backend\app\crud.py", line 32, in create_user
    db_user = models.User(
        email=user.email,
    ...<3 lines>...
        hashed_password=hashed_password
    )
  File "<string>", line 4, in __init__
  File "C:\Users\dipan\Documents\Code\lit-eracy\backend\.venv\Lib\site-packages\sqlalchemy\orm\state.py", line 571, in _initialize_instance
    with util.safe_reraise():
         ~~~~~~~~~~~~~~~~~^^
  File "C:\Users\dipan\Documents\Code\lit-eracy\backend\.venv\Lib\site-packages\sqlalchemy\util\langhelpers.py", line 146, in __exit__
    raise exc_value.with_traceback(exc_tb)
  File "C:\Users\dipan\Documents\Code\lit-eracy\backend\.venv\Lib\site-packages\sqlalchemy\orm\state.py", line 569, in _initialize_instance
    manager.original_init(*mixed[1:], **kwargs)
    ~~~~~~~~~~~~~~~~~~~~~^^^^^^^^^^^^^^^^^^^^^^
  File "C:\Users\dipan\Documents\Code\lit-eracy\backend\.venv\Lib\site-packages\sqlalchemy\orm\decl_base.py", line 2177, in _declarative_constructor
    raise TypeError(
        "%r is an invalid keyword argument for %s" % (k, cls_.__name__)
    )
TypeError: 'full_name' is an invalid keyword argument for User