INFO:     127.0.0.1:50306 - "POST /api/auth/login HTTP/1.1" 500 Internal Server Error
ERROR:    Exception in ASGI application
Traceback (most recent call last):
  File "C:\Users\dipan\Documents\Code\lit-eracy\backend\.venv\Lib\site-packages\uvicorn\protocols\http\httptools_impl.py", line 401, in run_asgi
    result = await app(  # type: ignore[func-returns-value]
             ^^^^^^^^^^^^^^^^^^^^^^^^^^^^^^^^^^^^^^^^^^^^^^
        self.scope, self.receive, self.send
        ^^^^^^^^^^^^^^^^^^^^^^^^^^^^^^^^^^^
    )
    ^
  File "C:\Users\dipan\Documents\Code\lit-eracy\backend\.venv\Lib\site-packages\uvicorn\middleware\proxy_headers.py", line 60, in __call__
    return await self.app(scope, receive, send)
           ^^^^^^^^^^^^^^^^^^^^^^^^^^^^^^^^^^^^
  File "C:\Users\dipan\Documents\Code\lit-eracy\backend\.venv\Lib\site-packages\fastapi\applications.py", line 1054, in __call__     
    await super().__call__(scope, receive, send)
  File "C:\Users\dipan\Documents\Code\lit-eracy\backend\.venv\Lib\site-packages\starlette\applications.py", line 113, in __call__    
    await self.middleware_stack(scope, receive, send)
  File "C:\Users\dipan\Documents\Code\lit-eracy\backend\.venv\Lib\site-packages\starlette\middleware\errors.py", line 187, in __call__
    raise exc
  File "C:\Users\dipan\Documents\Code\lit-eracy\backend\.venv\Lib\site-packages\starlette\middleware\errors.py", line 165, in __call__
    await self.app(scope, receive, _send)
  File "C:\Users\dipan\Documents\Code\lit-eracy\backend\.venv\Lib\site-packages\starlette\middleware\cors.py", line 93, in __call__  
    await self.simple_response(scope, receive, send, request_headers=headers)
  File "C:\Users\dipan\Documents\Code\lit-eracy\backend\.venv\Lib\site-packages\starlette\middleware\cors.py", line 144, in simple_response
    await self.app(scope, receive, send)
  File "C:\Users\dipan\Documents\Code\lit-eracy\backend\.venv\Lib\site-packages\starlette\middleware\exceptions.py", line 62, in __call__
    await wrap_app_handling_exceptions(self.app, conn)(scope, receive, send)
  File "C:\Users\dipan\Documents\Code\lit-eracy\backend\.venv\Lib\site-packages\starlette\_exception_handler.py", line 53, in wrapped_app
    raise exc
  File "C:\Users\dipan\Documents\Code\lit-eracy\backend\.venv\Lib\site-packages\starlette\_exception_handler.py", line 42, in wrapped_app
    await app(scope, receive, sender)
  File "C:\Users\dipan\Documents\Code\lit-eracy\backend\.venv\Lib\site-packages\starlette\routing.py", line 715, in __call__
    await self.middleware_stack(scope, receive, send)
  File "C:\Users\dipan\Documents\Code\lit-eracy\backend\.venv\Lib\site-packages\starlette\routing.py", line 735, in app
    await route.handle(scope, receive, send)
  File "C:\Users\dipan\Documents\Code\lit-eracy\backend\.venv\Lib\site-packages\starlette\routing.py", line 288, in handle
    await self.app(scope, receive, send)
  File "C:\Users\dipan\Documents\Code\lit-eracy\backend\.venv\Lib\site-packages\starlette\routing.py", line 76, in app
    await wrap_app_handling_exceptions(app, request)(scope, receive, send)
  File "C:\Users\dipan\Documents\Code\lit-eracy\backend\.venv\Lib\site-packages\starlette\_exception_handler.py", line 53, in wrapped_app
    raise exc
  File "C:\Users\dipan\Documents\Code\lit-eracy\backend\.venv\Lib\site-packages\starlette\_exception_handler.py", line 42, in wrapped_app
    await app(scope, receive, sender)
  File "C:\Users\dipan\Documents\Code\lit-eracy\backend\.venv\Lib\site-packages\starlette\routing.py", line 73, in app
    response = await f(request)
               ^^^^^^^^^^^^^^^^
  File "C:\Users\dipan\Documents\Code\lit-eracy\backend\.venv\Lib\site-packages\fastapi\routing.py", line 301, in app
    raw_response = await run_endpoint_function(
                   ^^^^^^^^^^^^^^^^^^^^^^^^^^^^
    ...<3 lines>...
    )
    ^
  File "C:\Users\dipan\Documents\Code\lit-eracy\backend\.venv\Lib\site-packages\fastapi\routing.py", line 212, in run_endpoint_function
    return await dependant.call(**values)
           ^^^^^^^^^^^^^^^^^^^^^^^^^^^^^^
  File "C:\Users\dipan\Documents\Code\lit-eracy\backend\app\routes\auth.py", line 39, in login
    user = authenticate_user_service(db, form_data.username, form_data.password)
  File "C:\Users\dipan\Documents\Code\lit-eracy\backend\app\services\auth.py", line 61, in authenticate_user_service
    return UserResponse.from_orm(user)
           ~~~~~~~~~~~~~~~~~~~~~^^^^^^
  File "C:\Users\dipan\Documents\Code\lit-eracy\backend\.venv\Lib\site-packages\pydantic\main.py", line 1236, in from_orm
    return cls.model_validate(obj)
           ~~~~~~~~~~~~~~~~~~^^^^^
  File "C:\Users\dipan\Documents\Code\lit-eracy\backend\.venv\Lib\site-packages\pydantic\main.py", line 567, in model_validate       
    return cls.__pydantic_validator__.validate_python(
           ~~~~~~~~~~~~~~~~~~~~~~~~~~~~~~~~~~~~~~~~~~^
        obj, strict=strict, from_attributes=from_attributes, context=context
        ^^^^^^^^^^^^^^^^^^^^^^^^^^^^^^^^^^^^^^^^^^^^^^^^^^^^^^^^^^^^^^^^^^^^
    )
    ^
pydantic_core._pydantic_core.ValidationError: 1 validation error for UserResponse
age
  Input should be a valid integer [type=int_type, input_value=None, input_type=NoneType]
    For further information visit https://errors.pydantic.dev/2.8/v/int_type
